<?xml version="1.0" encoding="UTF-8"?>
<testng-results ignored="0" total="3" passed="0" failed="3" skipped="0">
  <reporter-output>
  </reporter-output>
  <suite started-at="2025-05-19T11:08:30 IST" name="Default suite" finished-at="2025-05-19T11:08:41 IST" duration-ms="11243">
    <groups>
    </groups>
    <test started-at="2025-05-19T11:08:30 IST" name="Default test" finished-at="2025-05-19T11:08:41 IST" duration-ms="11243">
      <class name="tests.LoginTest">
        <test-method is-config="true" signature="setupReport()[pri:0, instance:tests.LoginTest@6cf0e0ba]" started-at="2025-05-19T11:08:29 IST" name="setupReport" finished-at="2025-05-19T11:08:30 IST" duration-ms="299" status="PASS">
          <reporter-output>
          </reporter-output>
        </test-method> <!-- setupReport -->
        <test-method is-config="true" signature="setup()[pri:0, instance:tests.LoginTest@6cf0e0ba]" started-at="2025-05-19T11:08:30 IST" name="setup" finished-at="2025-05-19T11:08:33 IST" duration-ms="3686" status="PASS">
          <reporter-output>
          </reporter-output>
        </test-method> <!-- setup -->
        <test-method signature="testValidLogin(java.lang.String,java.lang.String)[pri:0, instance:tests.LoginTest@6cf0e0ba]" started-at="2025-05-19T11:08:33 IST" name="testValidLogin" data-provider="LoginData2" finished-at="2025-05-19T11:08:34 IST" duration-ms="633" status="FAIL">
          <params>
            <param index="0">
              <value>
                <![CDATA[user1]]>
              </value>
            </param>
            <param index="1">
              <value>
                <![CDATA[pass1]]>
              </value>
            </param>
          </params>
          <exception class="java.lang.AssertionError">
            <message>
              <![CDATA[expected [Just a moment...] but found [nopCommerce demo store. Login]]]>
            </message>
            <full-stacktrace>
              <![CDATA[java.lang.AssertionError: expected [Just a moment...] but found [nopCommerce demo store. Login]
at org.testng.Assert.fail(Assert.java:111)
at org.testng.Assert.failNotEquals(Assert.java:1590)
at org.testng.Assert.assertEqualsImpl(Assert.java:150)
at org.testng.Assert.assertEquals(Assert.java:132)
at org.testng.Assert.assertEquals(Assert.java:656)
at org.testng.Assert.assertEquals(Assert.java:666)
at tests.LoginTest.testValidLogin(LoginTest.java:60)
at java.base/jdk.internal.reflect.DirectMethodHandleAccessor.invoke(DirectMethodHandleAccessor.java:104)
at java.base/java.lang.reflect.Method.invoke(Method.java:565)
at org.testng.internal.invokers.MethodInvocationHelper.invokeMethod(MethodInvocationHelper.java:141)
at org.testng.internal.invokers.TestInvoker.invokeMethod(TestInvoker.java:687)
at org.testng.internal.invokers.TestInvoker.invokeTestMethod(TestInvoker.java:230)
at org.testng.internal.invokers.MethodRunner.runInSequence(MethodRunner.java:63)
at org.testng.internal.invokers.TestInvoker$MethodInvocationAgent.invoke(TestInvoker.java:995)
at org.testng.internal.invokers.TestInvoker.invokeTestMethods(TestInvoker.java:203)
at org.testng.internal.invokers.TestMethodWorker.invokeTestMethods(TestMethodWorker.java:154)
at org.testng.internal.invokers.TestMethodWorker.run(TestMethodWorker.java:134)
at java.base/java.util.ArrayList.forEach(ArrayList.java:1604)
at org.testng.TestRunner.privateRun(TestRunner.java:741)
at org.testng.TestRunner.run(TestRunner.java:616)
at org.testng.SuiteRunner.runTest(SuiteRunner.java:421)
at org.testng.SuiteRunner.runSequentially(SuiteRunner.java:413)
at org.testng.SuiteRunner.privateRun(SuiteRunner.java:373)
at org.testng.SuiteRunner.run(SuiteRunner.java:312)
at org.testng.SuiteRunnerWorker.runSuite(SuiteRunnerWorker.java:52)
at org.testng.SuiteRunnerWorker.run(SuiteRunnerWorker.java:95)
at org.testng.TestNG.runSuitesSequentially(TestNG.java:1274)
at org.testng.TestNG.runSuitesLocally(TestNG.java:1208)
at org.testng.TestNG.runSuites(TestNG.java:1112)
at org.testng.TestNG.run(TestNG.java:1079)
at org.testng.remote.AbstractRemoteTestNG.run(AbstractRemoteTestNG.java:115)
at org.testng.remote.RemoteTestNG.initAndRun(RemoteTestNG.java:293)
at org.testng.remote.RemoteTestNG.main(RemoteTestNG.java:91)
]]>
            </full-stacktrace>
          </exception> <!-- java.lang.AssertionError -->
          <reporter-output>
          </reporter-output>
        </test-method> <!-- testValidLogin -->
        <test-method is-config="true" signature="tearDown(org.testng.ITestResult)[pri:0, instance:tests.LoginTest@6cf0e0ba]" started-at="2025-05-19T11:08:34 IST" name="tearDown" finished-at="2025-05-19T11:08:34 IST" duration-ms="300" status="PASS">
          <params>
            <param index="0">
              <value>
                <![CDATA[[TestResult name=testValidLogin status=FAILURE method=LoginTest.testValidLogin(java.lang.String,java.lang.String)[pri:0, instance:tests.LoginTest@6cf0e0ba] output={null}]]]>
              </value>
            </param>
          </params>
          <reporter-output>
          </reporter-output>
        </test-method> <!-- tearDown -->
        <test-method is-config="true" signature="setup()[pri:0, instance:tests.LoginTest@6cf0e0ba]" started-at="2025-05-19T11:08:34 IST" name="setup" finished-at="2025-05-19T11:08:37 IST" duration-ms="2362" status="PASS">
          <reporter-output>
          </reporter-output>
        </test-method> <!-- setup -->
        <test-method signature="testValidLogin(java.lang.String,java.lang.String)[pri:0, instance:tests.LoginTest@6cf0e0ba]" started-at="2025-05-19T11:08:37 IST" name="testValidLogin" data-provider="LoginData2" finished-at="2025-05-19T11:08:37 IST" duration-ms="602" status="FAIL">
          <params>
            <param index="0">
              <value>
                <![CDATA[user2]]>
              </value>
            </param>
            <param index="1">
              <value>
                <![CDATA[pass2]]>
              </value>
            </param>
          </params>
          <exception class="java.lang.AssertionError">
            <message>
              <![CDATA[expected [Just a moment...] but found [nopCommerce demo store. Login]]]>
            </message>
            <full-stacktrace>
              <![CDATA[java.lang.AssertionError: expected [Just a moment...] but found [nopCommerce demo store. Login]
at org.testng.Assert.fail(Assert.java:111)
at org.testng.Assert.failNotEquals(Assert.java:1590)
at org.testng.Assert.assertEqualsImpl(Assert.java:150)
at org.testng.Assert.assertEquals(Assert.java:132)
at org.testng.Assert.assertEquals(Assert.java:656)
at org.testng.Assert.assertEquals(Assert.java:666)
at tests.LoginTest.testValidLogin(LoginTest.java:60)
at java.base/jdk.internal.reflect.DirectMethodHandleAccessor.invoke(DirectMethodHandleAccessor.java:104)
at java.base/java.lang.reflect.Method.invoke(Method.java:565)
at org.testng.internal.invokers.MethodInvocationHelper.invokeMethod(MethodInvocationHelper.java:141)
at org.testng.internal.invokers.TestInvoker.invokeMethod(TestInvoker.java:687)
at org.testng.internal.invokers.TestInvoker.invokeTestMethod(TestInvoker.java:230)
at org.testng.internal.invokers.MethodRunner.runInSequence(MethodRunner.java:63)
at org.testng.internal.invokers.TestInvoker$MethodInvocationAgent.invoke(TestInvoker.java:995)
at org.testng.internal.invokers.TestInvoker.invokeTestMethods(TestInvoker.java:203)
at org.testng.internal.invokers.TestMethodWorker.invokeTestMethods(TestMethodWorker.java:154)
at org.testng.internal.invokers.TestMethodWorker.run(TestMethodWorker.java:134)
at java.base/java.util.ArrayList.forEach(ArrayList.java:1604)
at org.testng.TestRunner.privateRun(TestRunner.java:741)
at org.testng.TestRunner.run(TestRunner.java:616)
at org.testng.SuiteRunner.runTest(SuiteRunner.java:421)
at org.testng.SuiteRunner.runSequentially(SuiteRunner.java:413)
at org.testng.SuiteRunner.privateRun(SuiteRunner.java:373)
at org.testng.SuiteRunner.run(SuiteRunner.java:312)
at org.testng.SuiteRunnerWorker.runSuite(SuiteRunnerWorker.java:52)
at org.testng.SuiteRunnerWorker.run(SuiteRunnerWorker.java:95)
at org.testng.TestNG.runSuitesSequentially(TestNG.java:1274)
at org.testng.TestNG.runSuitesLocally(TestNG.java:1208)
at org.testng.TestNG.runSuites(TestNG.java:1112)
at org.testng.TestNG.run(TestNG.java:1079)
at org.testng.remote.AbstractRemoteTestNG.run(AbstractRemoteTestNG.java:115)
at org.testng.remote.RemoteTestNG.initAndRun(RemoteTestNG.java:293)
at org.testng.remote.RemoteTestNG.main(RemoteTestNG.java:91)
]]>
            </full-stacktrace>
          </exception> <!-- java.lang.AssertionError -->
          <reporter-output>
          </reporter-output>
        </test-method> <!-- testValidLogin -->
        <test-method is-config="true" signature="tearDown(org.testng.ITestResult)[pri:0, instance:tests.LoginTest@6cf0e0ba]" started-at="2025-05-19T11:08:37 IST" name="tearDown" finished-at="2025-05-19T11:08:37 IST" duration-ms="282" status="PASS">
          <params>
            <param index="0">
              <value>
                <![CDATA[[TestResult name=testValidLogin status=FAILURE method=LoginTest.testValidLogin(java.lang.String,java.lang.String)[pri:0, instance:tests.LoginTest@6cf0e0ba] output={null}]]]>
              </value>
            </param>
          </params>
          <reporter-output>
          </reporter-output>
        </test-method> <!-- tearDown -->
        <test-method is-config="true" signature="setup()[pri:0, instance:tests.LoginTest@6cf0e0ba]" started-at="2025-05-19T11:08:37 IST" name="setup" finished-at="2025-05-19T11:08:40 IST" duration-ms="2292" status="PASS">
          <reporter-output>
          </reporter-output>
        </test-method> <!-- setup -->
        <test-method signature="testValidLogin(java.lang.String,java.lang.String)[pri:0, instance:tests.LoginTest@6cf0e0ba]" started-at="2025-05-19T11:08:40 IST" name="testValidLogin" data-provider="LoginData2" finished-at="2025-05-19T11:08:40 IST" duration-ms="515" status="FAIL">
          <params>
            <param index="0">
              <value>
                <![CDATA[user3]]>
              </value>
            </param>
            <param index="1">
              <value>
                <![CDATA[pass3]]>
              </value>
            </param>
          </params>
          <exception class="java.lang.AssertionError">
            <message>
              <![CDATA[expected [Just a moment...] but found [nopCommerce demo store. Login]]]>
            </message>
            <full-stacktrace>
              <![CDATA[java.lang.AssertionError: expected [Just a moment...] but found [nopCommerce demo store. Login]
at org.testng.Assert.fail(Assert.java:111)
at org.testng.Assert.failNotEquals(Assert.java:1590)
at org.testng.Assert.assertEqualsImpl(Assert.java:150)
at org.testng.Assert.assertEquals(Assert.java:132)
at org.testng.Assert.assertEquals(Assert.java:656)
at org.testng.Assert.assertEquals(Assert.java:666)
at tests.LoginTest.testValidLogin(LoginTest.java:60)
at java.base/jdk.internal.reflect.DirectMethodHandleAccessor.invoke(DirectMethodHandleAccessor.java:104)
at java.base/java.lang.reflect.Method.invoke(Method.java:565)
at org.testng.internal.invokers.MethodInvocationHelper.invokeMethod(MethodInvocationHelper.java:141)
at org.testng.internal.invokers.TestInvoker.invokeMethod(TestInvoker.java:687)
at org.testng.internal.invokers.TestInvoker.invokeTestMethod(TestInvoker.java:230)
at org.testng.internal.invokers.MethodRunner.runInSequence(MethodRunner.java:63)
at org.testng.internal.invokers.TestInvoker$MethodInvocationAgent.invoke(TestInvoker.java:995)
at org.testng.internal.invokers.TestInvoker.invokeTestMethods(TestInvoker.java:203)
at org.testng.internal.invokers.TestMethodWorker.invokeTestMethods(TestMethodWorker.java:154)
at org.testng.internal.invokers.TestMethodWorker.run(TestMethodWorker.java:134)
at java.base/java.util.ArrayList.forEach(ArrayList.java:1604)
at org.testng.TestRunner.privateRun(TestRunner.java:741)
at org.testng.TestRunner.run(TestRunner.java:616)
at org.testng.SuiteRunner.runTest(SuiteRunner.java:421)
at org.testng.SuiteRunner.runSequentially(SuiteRunner.java:413)
at org.testng.SuiteRunner.privateRun(SuiteRunner.java:373)
at org.testng.SuiteRunner.run(SuiteRunner.java:312)
at org.testng.SuiteRunnerWorker.runSuite(SuiteRunnerWorker.java:52)
at org.testng.SuiteRunnerWorker.run(SuiteRunnerWorker.java:95)
at org.testng.TestNG.runSuitesSequentially(TestNG.java:1274)
at org.testng.TestNG.runSuitesLocally(TestNG.java:1208)
at org.testng.TestNG.runSuites(TestNG.java:1112)
at org.testng.TestNG.run(TestNG.java:1079)
at org.testng.remote.AbstractRemoteTestNG.run(AbstractRemoteTestNG.java:115)
at org.testng.remote.RemoteTestNG.initAndRun(RemoteTestNG.java:293)
at org.testng.remote.RemoteTestNG.main(RemoteTestNG.java:91)
]]>
            </full-stacktrace>
          </exception> <!-- java.lang.AssertionError -->
          <reporter-output>
          </reporter-output>
        </test-method> <!-- testValidLogin -->
        <test-method is-config="true" signature="tearDown(org.testng.ITestResult)[pri:0, instance:tests.LoginTest@6cf0e0ba]" started-at="2025-05-19T11:08:40 IST" name="tearDown" finished-at="2025-05-19T11:08:41 IST" duration-ms="519" status="PASS">
          <params>
            <param index="0">
              <value>
                <![CDATA[[TestResult name=testValidLogin status=FAILURE method=LoginTest.testValidLogin(java.lang.String,java.lang.String)[pri:0, instance:tests.LoginTest@6cf0e0ba] output={null}]]]>
              </value>
            </param>
          </params>
          <reporter-output>
          </reporter-output>
        </test-method> <!-- tearDown -->
        <test-method is-config="true" signature="teardownReport()[pri:0, instance:tests.LoginTest@6cf0e0ba]" started-at="2025-05-19T11:08:41 IST" name="teardownReport" finished-at="2025-05-19T11:08:41 IST" duration-ms="268" status="PASS">
          <reporter-output>
          </reporter-output>
        </test-method> <!-- teardownReport -->
      </class> <!-- tests.LoginTest -->
    </test> <!-- Default test -->
  </suite> <!-- Default suite -->
</testng-results>
